<!DOCTYPE html>
<html lang="en">
<head>
    <meta charset="UTF-8">
    <title>Promise题目</title>
</head>
<body>
<script>
    Promise.resolve()
        .then(() => {
            return new Error('error!!!')
        })
        .then((res) => {
            console.log('then: ', res) //输出:then: Error: error!!!
        })
        .catch((err) => {
            console.log('catch: ', err)
        })

    /*
    *解释：.then 或者 .catch 中 return 一个 error 对象并不会抛出错误，所以不会被后续的 .catch 捕获，需要改成其中一种：
        1.return Promise.reject(new Error('error!!!'))
        2.throw new Error('error!!!')
    因为返回任意一个非 promise 的值都会被包裹成 promise 对象，即 return new Error('error!!!') 等价于 return Promise.resolve(new Error('error!!!'))。
    */


    Promise.resolve(1)
        .then(2)
        .then(Promise.resolve(3))
        .then(data=>console.log(data)); //1

    /*
    *   解释：.then 或者 .catch 的参数期望是函数，传入非函数则会发生值穿透。
    */
</script>
</body>
</html>